<?xml version="1.0" ?>
<!-- =================================================================================== -->
<!-- |    This document was autogenerated by xacro from syogouki_display.xacro         | -->
<!-- |    EDITING THIS FILE BY HAND IS NOT RECOMMENDED                                 | -->
<!-- =================================================================================== -->
<robot name="test_robot">
  <material name="body_colors">
    <color rgba="0.02 0.52 0.86 2.0"/>
  </material>
  <material name="flipper_colors">
    <color rgba="0.02 0.52 0.86 2.0"/>
  </material>
  <material name="flipper_belt_colors">
    <color rgba="0.224 0.72 0.556 2.0"/>
  </material>
  <material name="table_colors">
    <color rgba="0.9 0.9 0.9 2.0"/>
  </material>
  <material name="gear_colors">
    <color rgba="0.9 0.9 0.9 2.0"/>
  </material>
  <material name="link_colors">
    <color rgba="0.7 0.7 0.7 2.0"/>
  </material>
  <material name="hands_colors">
    <color rgba="0.2 0.211 0.192 2.0"/>
  </material>
  <link name="base_link"/>
  <joint name="xprismatic" type="prismatic">
    <parent link="base_link"/>
    <child link="main_body_xprismatic"/>
    <axis xyz="1 0 0"/>
    <limit effort="10000.0" lower="-1000" upper="1000" velocity="0.5"/>
    <origin rpy="0 0 0" xyz="0 0 0.081169"/>
  </joint>
  <joint name="yprismatic" type="prismatic">
    <parent link="main_body_xprismatic"/>
    <child link="main_body_yprismatic"/>
    <axis xyz="0 1 0"/>
    <limit effort="10000.0" lower="-1000" upper="1000" velocity="0.5"/>
    <origin rpy="0 0 0" xyz="0 0 0"/>
  </joint>
  <joint name="xaxis" type="revolute">
    <parent link="main_body_yprismatic"/>
    <child link="main_body_xaxis"/>
    <axis xyz="1 0 0"/>
    <limit effort="10000.0" lower="-3.141592653589793" upper="3.141592653589793" velocity="0.5"/>
    <origin rpy="0 0 0" xyz="0 0 0"/>
  </joint>
  <joint name="yaxis" type="revolute">
    <parent link="main_body_xaxis"/>
    <child link="main_body_yaxis"/>
    <axis xyz="0 1 0"/>
    <limit effort="10000.0" lower="-3.141592653589793" upper="3.141592653589793" velocity="0.5"/>
    <origin rpy="0 0 0" xyz="0 0 0"/>
  </joint>
  <joint name="zaxis" type="revolute">
    <parent link="main_body_yaxis"/>
    <child link="main_body_zaxis"/>
    <axis xyz="0 0 1"/>
    <limit effort="10000.0" lower="-3.141592653589793" upper="3.141592653589793" velocity="0.5"/>
    <origin rpy="0 0 0" xyz="0 0 0"/>
  </joint>
  <joint name="2main_body" type="fixed">
    <parent link="main_body_zaxis"/>
    <child link="main_body"/>
    <origin rpy="0 0 0" xyz="0 0 0"/>
  </joint>
  <link name="main_body_xprismatic"/>
  <link name="main_body_yprismatic"/>
  <link name="main_body_xaxis"/>
  <link name="main_body_yaxis"/>
  <link name="main_body_zaxis"/>
  <link name="main_body">
    <visual>
      <geometry>
        <mesh filename="package://syogouki_display/mesh/body/main_body.stl" scale="0.001 0.001 0.001"/>
      </geometry>
      <material name="body_colors"/>
    </visual>
  </link>
  <joint name="left_front" type="revolute">
    <parent link="main_body"/>
    <child link="left_front"/>
    <axis xyz="1 0 0"/>
    <limit effort="1000" lower="-2.356194490192345" upper="2.356194490192345" velocity="0.5"/>
    <origin rpy="0 0 0" xyz="1.6 -1.0 0.5"/>
  </joint>
  <link name="left_front">
    <visual>
      <geometry>
        <mesh filename="package://syogouki_display/mesh/body/flipper_without_belt.stl" scale="0.001 0.001 0.001"/>
      </geometry>
      <origin rpy="0 0 0" xyz="0 -2.0 0"/>
      <material name="flipper_colors"/>
    </visual>
  </link>
  <joint name="left_rear" type="revolute">
    <parent link="main_body"/>
    <child link="left_rear"/>
    <axis xyz="1 0 0"/>
    <limit effort="1000" lower="-2.356194490192345" upper="2.356194490192345" velocity="0.5"/>
    <origin rpy="0 0 0" xyz="1.6 1.0 0.5"/>
  </joint>
  <link name="left_rear">
    <visual>
      <geometry>
        <mesh filename="package://syogouki_display/mesh/body/flipper_without_belt.stl" scale="0.001 0.001 0.001"/>
      </geometry>
      <origin rpy="0 0 0" xyz="0 0.0 0"/>
      <material name="flipper_colors"/>
    </visual>
  </link>
  <joint name="right_front" type="revolute">
    <parent link="main_body"/>
    <child link="right_front"/>
    <axis xyz="1 0 0"/>
    <limit effort="1000" lower="-2.356194490192345" upper="2.356194490192345" velocity="0.5"/>
    <origin rpy="0 0 0" xyz="-1.6 -1.0 0.5"/>
  </joint>
  <link name="right_front">
    <visual>
      <geometry>
        <mesh filename="package://syogouki_display/mesh/body/flipper_without_belt.stl" scale="0.001 0.001 0.001"/>
      </geometry>
      <origin rpy="0 0 0" xyz="0 -2.0 0"/>
      <material name="flipper_colors"/>
    </visual>
  </link>
  <joint name="right_rear" type="revolute">
    <parent link="main_body"/>
    <child link="right_rear"/>
    <axis xyz="1 0 0"/>
    <limit effort="1000" lower="-2.356194490192345" upper="2.356194490192345" velocity="0.5"/>
    <origin rpy="0 0 0" xyz="-1.6 1.0 0.5"/>
  </joint>
  <link name="right_rear">
    <visual>
      <geometry>
        <mesh filename="package://syogouki_display/mesh/body/flipper_without_belt.stl" scale="0.001 0.001 0.001"/>
      </geometry>
      <origin rpy="0 0 0" xyz="0 0.0 0"/>
      <material name="flipper_colors"/>
    </visual>
  </link>
  <!--LR: left or right-->
  <joint name="2table" type="fixed">
    <parent link="main_body"/>
    <child link="link_table"/>
    <origin rpy="0 0 0" xyz="0 0 0.9"/>
  </joint>
  <joint name="turn_table" type="revolute">
    <parent link="link_table"/>
    <child link="link_turn"/>
    <limit effort="10000.0" lower="-3.141592653589793" upper="3.141592653589793" velocity="0.5"/>
    <axis xyz="0 0 1"/>
    <origin rpy="0 0 0" xyz="0 -0.8 0.6"/>
    <!--origin xyz="${0.154*0.001} ${-10.0*0.1} 0.7}" rpy="0 0 0"/>-->
  </joint>
  <joint name="first_link" type="revolute">
    <parent link="link_turn"/>
    <child link="link_first_link"/>
    <axis xyz="-1 0 0"/>
    <limit effort="10000.0" lower="-3.141592653589793" upper="3.141592653589793" velocity="0.5"/>
    <origin rpy="0 0 0" xyz="0 0 0.45"/>
    <!--origin xyz="${0.001*2.617} ${0.001*4.552} ${0.001*54}" rpy="0 0 0"/>-->
  </joint>
  <joint name="second_link" type="revolute">
    <parent link="link_first_link"/>
    <child link="link_second_link"/>
    <axis xyz="1 0 0"/>
    <limit effort="10000.0" lower="-3.141592653589793" upper="3.141592653589793" velocity="0.5"/>
    <origin rpy="0 0 0" xyz="0 2.4 0.5"/>
  </joint>
  <joint name="hand_base" type="fixed">
    <parent link="link_second_link"/>
    <child link="link_hand_base"/>
    <origin rpy="0 0 0" xyz="0 -2.5 0"/>
  </joint>
  <joint name="hand_roll" type="revolute">
    <!--parent link="link_hand_pitch"/-->
    <!--child  link="link_hand_roll"/-->
    <parent link="link_hand_base"/>
    <child link="link_hand_roll"/>
    <axis xyz="1 0 0"/>
    <limit effort="10000.0" lower="-3.141592653589793" upper="3.141592653589793" velocity="0.5"/>
    <origin rpy="0 0 0" xyz="0 0 0"/>
  </joint>
  <joint name="hand_yaw" type="revolute">
    <!--parent link="link_hand_base"/>
      <child  link="link_hand_yaw"/>-->
    <parent link="link_hand_roll"/>
    <child link="link_hand_yaw"/>
    <axis xyz="0 0 1"/>
    <limit effort="10000.0" lower="-3.141592653589793" upper="3.141592653589793" velocity="0.5"/>
    <origin rpy="0 0 0" xyz="0 -0.8 0"/>
  </joint>
  <joint name="hand_pitch" type="revolute">
    <parent link="link_hand_yaw"/>
    <child link="link_hand_pitch"/>
    <axis xyz="0 1 0"/>
    <limit effort="10000.0" lower="-3.141592653589793" upper="3.141592653589793" velocity="0.5"/>
    <origin rpy="0 0 0" xyz="0 -0.3 0.013778"/>
  </joint>
  <link name="link_table">
    <visual>
      <geometry>
        <mesh filename="package://syogouki_display/mesh/manipulator/table/tables.stl" scale="0.01 0.01 0.01"/>
      </geometry>
      <material name="table_colors"/>
    </visual>
  </link>
  <link name="link_turn">
    <visual>
      <geometry>
        <mesh filename="package://syogouki_display/mesh/manipulator/table/arm_base.stl" scale="0.001 0.001 0.001"/>
      </geometry>
      <origin rpy="0 0 0" xyz="0 0 0"/>
      <material name="gear_colors"/>
    </visual>
  </link>
  <link name="link_first_link">
    <visual>
      <geometry>
        <mesh filename="package://syogouki_display/mesh/manipulator/link/first_link.stl" scale="0.01 0.01 0.01"/>
      </geometry>
      <origin rpy="0 0 0" xyz="0 0 -0.4"/>
      <material name="link_colors"/>
    </visual>
  </link>
  <link name="link_second_link">
    <visual>
      <geometry>
        <mesh filename="package://syogouki_display/mesh/manipulator/link/second_link.stl" scale="0.001 0.001 0.001"/>
      </geometry>
      <material name="link_colors"/>
    </visual>
  </link>
  <link name="link_hand_base">
    <visual>
      <geometry>
        <mesh filename="package://syogouki_display/mesh/manipulator/hands/hand_base.stl" scale="0.001 0.001 0.001"/>
      </geometry>
      <material name="hands_colors"/>
    </visual>
  </link>
  <link name="link_hand_roll">
    <visual>
      <geometry>
        <mesh filename="package://syogouki_display/mesh/manipulator/hands/hand_roll.stl" scale="0.01 0.01 0.01"/>
      </geometry>
      <material name="hands_colors"/>
    </visual>
  </link>
  <link name="link_hand_yaw">
    <visual>
      <geometry>
        <mesh filename="package://syogouki_display/mesh/manipulator/hands/hand_yaw.stl" scale="0.01 0.01 0.01"/>
      </geometry>
      <material name="hands_colors"/>
    </visual>
  </link>
  <link name="link_hand_pitch">
    <visual>
      <geometry>
        <mesh filename="package://syogouki_display/mesh/manipulator/hands/hand_pitch.stl" scale="0.01 0.01 0.01"/>
      </geometry>
      <material name="hands_colors"/>
    </visual>
  </link>
</robot>

